Workbook

Sheet Сводка
C3: И Т О Г О С Н Д С 2 2 %
C4: =Смета!$G$53
C5: без НДС | D5: =Смета!$G$51
C6: НДС 22% | D6: =Смета!$G$52
C7: Три версии фильма: к 35-летию 4–5 минут, партнёрская 2:30–3:00, для HH.ru 60–90 секунд. Русский язык, съёмки в Москве, Валищево, Нижнем Новгороде, Петербурге, Минске и Алматы, озвучка, графика, карта, музыка. Три круга правок включены.
C9: О Б Ъ Ё М Р А Б О Т Ы
C10: 12 | D10: съёмочных смен | F10: по 12 часов, группа из трёх человек на каждой
C11: 6 | D11: площадок | F11: офис в Москве, Валищево, Нижний Новгород, Петербург, Минск, Алматы
C12: ≈9 600 | D12: км перелётов | F12: 4 командировки туда и обратно, техника летит с группой
C13: 6 | D13: месяцев | F13: с февраля по июль 2027, сдача 26 июля
C15: В О Ч Т О Э Т О С К Л А Д Ы В А Е Т С Я
C16: Раздел | D16: Сумма, ₽ | E16: Доля
C17: 01 Подготовка | D17: =Смета!G5 | E17: =IF(Смета!$G$51=0,0,D17/Смета!$G$51) | F17: =REPT("█",ROUND(E17*80,0))
C18: 02 Съёмки и командировки | D18: =Смета!G13 | E18: =IF(Смета!$G$51=0,0,D18/Смета!$G$51) | F18: =REPT("█",ROUND(E18*80,0))
C19: 03 Архив и стоки | D19: =Смета!G22 | E19: =IF(Смета!$G$51=0,0,D19/Смета!$G$51) | F19: =REPT("█",ROUND(E19*80,0))
C20: 04 Монтаж и цвет | D20: =Смета!G26 | E20: =IF(Смета!$G$51=0,0,D20/Смета!$G$51) | F20: =REPT("█",ROUND(E20*80,0))
C21: 05 Дизайн и графика | D21: =Смета!G33 | E21: =IF(Смета!$G$51=0,0,D21/Смета!$G$51) | F21: =REPT("█",ROUND(E21*80,0))
C22: 06 Звук и озвучка | D22: =Смета!G41 | E22: =IF(Смета!$G$51=0,0,D22/Смета!$G$51) | F22: =REPT("█",ROUND(E22*80,0))
C23: 07 Продюсирование | D23: =Смета!G47 | E23: =IF(Смета!$G$51=0,0,D23/Смета!$G$51) | F23: =REPT("█",ROUND(E23*80,0))
C24: Итого без НДС | D24: =Смета!$G$51
C25: По желанию, в итог не входит | D25: =SUM(Смета!G57:G59)
C27: К А К У С Т Р О Е Н Ф А Й Л
C28: Смета | D28: все строки по разделам, у каждой пояснение, что входит и зачем
C29: Съёмки | D29: расчёт по каждому городу: группа, техника, перелёт, гостиница, трансферы, суточные
C30: Ставки | D30: ставки группы, техника, суточные, НДС
C31: Вопросы | D31: почему трое, почему две смены, где можно сэкономить
C33: жёлтое можно менять | D33: итоги и доли пересчитаются сами
C35: Живая версия с пояснениями: hand-marketing.ru/for/alidi (пароль alidi)
B37: Hand Marketing · hand-marketing.ru · +7 985 999 87 83 · anarodetsky@hand-marketing.ru

Sheet Смета
B3: № | C3: Статья | D3: Ед. | E3: Кол-во | F3: Цена, ₽ | G3: Сумма, ₽ | H3: Комментарий | I3: Что входит и зачем
B5: 01 | C5: Подготовка | G5: =SUM(G6:G11) | H5: Всё, что делаем до первого дня съёмок: от идеи до списка кадров на каждую площадку.
B6: 1.1 | C6: Две концепции до сценария (ТЗ просит две) | D6: сценарий | E6: 2 | F6: 110000 | G6: =E6*F6 | H6: идея, структура, закадровый текст, хронометраж | I6: ТЗ просит две концепции на выбор. Каждую доводим до сценария: структура, закадровый текст, кто в кадре и сколько длится каждая часть. Вы выбираете одну, по ней снимаем. Пять идей с этой страницы служат отправной точкой.
B7: 1.2 | C7: Раскадровка выбранного сценария | D7: комплект | E7: 1 | F7: 60000 | G7: =E7*F7 | H7: кадры по сценам, как в раскадровках от 7 октября | I7: Сценарий в картинках: каждая сцена нарисована кадрами, как в карандашных раскадровках, которые мы показывали 7 октября. Генеральный директор видит фильм до съёмок, группа знает, что снимать.
B8: 1.3 | C8: Экспликация и шотлисты на 6 площадок | D8: комплект | E8: 1 | F8: 70000 | G8: =E8*F8 | H8: единый список действий и формулы кадров для всех городов | I8: Для каждой площадки список кадров: что снимаем, с какой точки, в какое время и с кем. Формулы кадров одинаковые во всех городах, поэтому Минск и Алматы выглядят как одна компания.
B9: 1.4 | C9: Подбор героев и вопросы для интервью | D9: комплект | E9: 1 | F9: 50000 | G9: =E9*F9 | H9: вместе с HR: стаж, должности, реплики | I9: Вместе с HR выбираем сотрудников для кадра и коротких реплик, готовим вопросы руководителям. Интервью проходит быстрее, когда человек заранее знает темы.
B10: 1.5 | C10: Технический выезд: Москва и Валищево | D10: день | E10: 1 | F10: 30000 | G10: =E10*F10 | H10: точки, свет, маршруты; остальные площадки по видеосвязи и фото | I10: До съёмок приезжаем в офис и в Валищево: смотрим свет, точки, маршруты, где встать ночью. Остальные города готовим по видеосвязи и фото с площадок, без отдельной поездки.
B11: 1.6 | C11: Сверка фактов и цифр, таблица для заполнения | D11: комплект | E11: 1 | F11: 30000 | G11: =E11*F11 | H11: склады, площади, бренды, сотрудники, награды | I11: Присылаем таблицу: склады, площади, бренды, сотрудники, награды. Вы заполняете, мы сверяем с сайтом и ТЗ. В кадр идёт только подтверждённая цифра с датой.
B13: 02 | C13: Съёмки и командировки | G13: =SUM(G14:G20) | H13: Смена до 12 часов на площадке. Едет группа из трёх человек с нашей техникой, ниже расчёт по каждому городу.
B14: 2.1 | C14: =Съёмки!B5 | D14: смена | E14: =Съёмки!D5 | F14: =IF(E14=0,0,G14/E14) | G14: =Съёмки!R5 | H14: =Съёмки!C5 | I14: Москва без командировки: группа, техника и трансфер команды с техникой до офиса.
B15: 2.2 | C15: =Съёмки!B6 | D15: смена | E15: =Съёмки!D6 | F15: =IF(E15=0,0,G15/E15) | G15: =Съёмки!R6 | H15: =Съёмки!C6 | I15: Две смены: дневная и ночная смена склада отдельным выездом.
B16: 2.3 | C16: =Съёмки!B7 | D16: смена | E16: =Съёмки!D7 | F16: =IF(E16=0,0,G16/E16) | G16: =Съёмки!R7 | H16: =Съёмки!C7 | I16: группа, техника, перелёт, гостиница, трансферы команды и техники, суточные: расчёт на листе «Съёмки»
B17: 2.4 | C17: =Съёмки!B8 | D17: смена | E17: =Съёмки!D8 | F17: =IF(E17=0,0,G17/E17) | G17: =Съёмки!R8 | H17: =Съёмки!C8 | I17: группа, техника, перелёт, гостиница, трансферы команды и техники, суточные: расчёт на листе «Съёмки»
B18: 2.5 | C18: =Съёмки!B9 | D18: смена | E18: =Съёмки!D9 | F18: =IF(E18=0,0,G18/E18) | G18: =Съёмки!R9 | H18: =Съёмки!C9 | I18: группа, техника, перелёт, гостиница, трансферы команды и техники, суточные: расчёт на листе «Съёмки»
B19: 2.6 | C19: =Съёмки!B10 | D19: смена | E19: =Съёмки!D10 | F19: =IF(E19=0,0,G19/E19) | G19: =Съёмки!R10 | H19: =Съёмки!C10 | I19: группа, техника, перелёт, гостиница, трансферы команды и техники, суточные: расчёт на листе «Съёмки»
B20: 2.7 | C20: =Съёмки!B11 | D20: смена | E20: =Съёмки!D11 | F20: =IF(E20=0,0,G20/E20) | G20: =Съёмки!R11 | H20: =Съёмки!C11 | I20: Запас на погоду, перенос и доборы: кадры, которые не получилось снять в свой день.
B22: 03 | C22: Архив и стоки | G22: =SUM(G23:G24) | H22: То, что не снимаем сами: история компании с 1992 года и места, где АЛИДИ работает незаметно.
B23: 3.1 | C23: Оцифровка и реставрация архива с 1992 года | D23: комплект | E23: 1 | F23: 40000 | G23: =E23*F23 | H23: фото и видео компании, до 60 единиц | I23: Сканируем и чистим фото и видео из архива компании, до 60 единиц. Нужно для истории в версии к 35-летию.
B24: 3.2 | C24: Стоковые кадры: розница, HoReCa, АЗС, малые филиалы | D24: клип | E24: 15 | F24: 6000 | G24: =E24*F24 | H24: без чужих логотипов, лицензия на все версии | I24: Магазины, кафе, АЗС и маленькие филиалы вроде Калининграда снимать отдельно дорого. Берём лицензионные кадры без чужих логотипов, лицензия покрывает все три версии. Заложили 15 клипов.
B26: 04 | C26: Монтаж и цвет | G26: =SUM(G27:G31) | H26: Три версии собираем отдельно, у каждой свой зритель и своя драматургия.
B27: 4.1 | C27: Разбор и синхронизация материала 12 смен | D27: комплект | E27: 1 | F27: 60000 | G27: =E27*F27 | H27: логирование, отбор дублей, расшифровка интервью | I27: 12 смен дают много часов материала. Расшифровываем интервью, отбираем лучшие дубли и раскладываем по сценам. Без этого монтаж идёт дольше и стоит дороже.
B28: 4.2 | C28: Монтаж: фильм к 35-летию, 4–5 минут | D28: версия | E28: 1 | F28: 220000 | G28: =E28*F28 | H28: три круга правок включены | I28: Главная версия для большого экрана на дне рождения компании. Три круга правок включены.
B29: 4.3 | C29: Монтаж: партнёрская версия, 2:30–3:00 | D29: версия | E29: 1 | F29: 140000 | G29: =E29*F29 | H29: монтируется отдельно, своя драматургия | I29: Не обрезка длинной версии, а отдельный монтаж: на переговорах и тендерах важнее масштаб и цифры, чем история. Три круга правок включены.
B30: 4.4 | C30: Монтаж: HR-версия для HH.ru, 60–90 секунд | D30: версия | E30: 1 | F30: 80000 | G30: =E30*F30 | H30: вертикаль 9:16, смысл держится без звука | I30: Вертикальное видео для телефона и HH.ru. Ленту листают без звука, поэтому смысл держится на кадре и титрах. Три круга правок включены.
B31: 4.5 | C31: Цветокоррекция: единый грейд всех площадок | D31: комплект | E31: 1 | F31: 140000 | G31: =E31*F31 | H31: три страны и шесть площадок выглядят как одна компания | I31: Шесть площадок снимаем в разные дни, при разной погоде и свете. Цветокоррекция приводит их к одному виду, а в «Сутках без остановки» ещё и ведёт цвет по времени дня.
B33: 05 | C33: Дизайн и графика | G33: =SUM(G34:G39) | H33: Всё, что появляется поверх кадра: карта, цифры, подписи, переходы.
B34: 5.1 | C34: Дизайн-концепция графики по брендбуку | D34: комплект | E34: 1 | F34: 90000 | G34: =E34*F34 | H34: стилфреймы, шрифты, треугольник «А» как знак | I34: Сначала показываем несколько кадров с графикой в стиле вашего брендбука: шрифты, цвета, треугольник «А». Вы утверждаете стиль, дальше вся графика делается в нём.
B35: 5.2 | C35: Анимированная карта: Россия, Беларусь, Казахстан | D35: комплект | E35: 1 | F35: 180000 | G35: =E35*F35 | H35: точки всплывают, на каждую короткий кадр | I35: Три страны на одной карте, точки всплывают от Калининграда до Алматы, на каждую короткий кадр с площадки. Примеры из наших роликов есть ниже на странице, в блоке «Карта в фильме».
B36: 5.3 | C36: Инфографика: цифры и факты в кадре | D36: плашка | E36: 12 | F36: 15000 | G36: =E36*F36 | H36: склады, площади, бренды, люди, по одной цифре на кадр | I36: Анимированные цифры поверх живых кадров: склады, площади, бренды, сотрудники. Одна цифра на кадр, чтобы успели прочитать. Заложили 12, точное число зависит от сценария.
B37: 5.4 | C37: Подписи героев, титры, заставки | D37: комплект | E37: 1 | F37: 70000 | G37: =E37*F37 | H37: имена и должности, открывающий и финальный титры | I37: Имя и должность у каждого героя, открывающий и финальный титры, заставки между частями фильма.
B38: 5.5 | C38: Анимированные объекты и переходы | D38: комплект | E38: 1 | F38: 90000 | G38: =E38*F38 | H38: метка времени, переходы между городами | I38: Метка времени в кадре, переходы между городами, фирменный знак в движении.
B39: 5.6 | C39: Адаптация графики под вертикаль | D39: комплект | E39: 1 | F39: 50000 | G39: =E39*F39 | H39: HR-версия | I39: Графику горизонтальной версии перекомпоновываем под экран телефона, иначе текст не читается.
B41: 06 | C41: Звук и озвучка | G41: =SUM(G42:G45) | H41: Голос диктора, музыка и чистый звук интервью для трёх версий.
B42: 6.1 | C42: Диктор: запись трёх версий в студии | D42: версия | E42: 3 | F42: 25000 | G42: =E42*F42 | H42: профессиональный голос, права на использование | I42: Профессиональный диктор, запись в студии, права на голос во всех версиях. У каждой версии свой текст, поэтому три записи.
B43: 6.2 | C43: Музыка: лицензия на трек | D43: трек | E43: 3 | F43: 25000 | G43: =E43*F43 | H43: расширенная лицензия, все площадки показа | I43: Лицензионный трек на каждую версию. Расширенная лицензия разрешает показ на мероприятии, на сайте, в соцсетях и на HH.ru.
B44: 6.3 | C44: Звук: чистка интервью, монтаж и сведение | D44: версия | E44: 3 | F44: 30000 | G44: =E44*F44 | H44: зал, ТВ и ПК, телефон | I44: Убираем из интервью шум склада, сводим голос, музыку и шумы. Отдельно под зал, ТВ и компьютер, отдельно под телефон.
B45: 6.4 | C45: Вшитые субтитры | D45: версия | E45: 3 | F45: 8000 | G45: =E45*F45 | H45: фильм понятен без звука | I45: Ключевые фразы вшиты в кадр. Фильм понятен без звука: на тендере и в ленте его часто смотрят именно так.
B47: 07 | C47: Продюсирование | G47: =SUM(G48:G49) | H47: Один человек ведёт проект с февраля по июль 2027 года и отвечает за сроки.
B48: 7.1 | C48: Продюсер проекта, единое окно | D48: месяц | E48: 6 | F48: 50000 | G48: =E48*F48 | H48: февраль–июль 2027: даты по загрузке складов, логистика, согласования | I48: Ваш контакт с февраля по июль 2027 года: согласует даты по загрузке складов, бронирует поездки, собирает правки и отвечает за сроки.
B49: 7.2 | C49: Мастер-файлы и хранение исходников | D49: комплект | E49: 1 | F49: 20000 | G49: =E49*F49 | H49: выгрузка под зал, ТВ, ПК и HH.ru; исходники хранятся 3 года | I49: Готовые файлы под каждый экран: зал, ТВ, компьютер, телефон. Исходники храним три года на случай перемонтажа.
...

Sheet Ставки
B3: С Ъ Ё М О Ч Н А Я Г Р У П П А Н А О Д Н У С М Е Н У , Д О 1 2 Ч А С О В
B4: Режиссёр-оператор | C4: ставит и снимает, одна рука на все площадки | D4: 45000
B5: Техник | C5: свет, звук, второй ракурс на интервью, данные | D5: 22000
B6: Куратор сценария и съёмки | C6: шотлист, герои, реплики, логотипы и форма в кадре | D6: 22000
B7: Группа за смену | D7: =SUM(D4:D6)
B9: О С Т А Л Ь Н Ы Е В В О Д Н Ы Е
B10: Человек в группе | C10: едут на каждую площадку | D10: 3
B11: Комплект техники на смену | C11: камера, оптика, свет, звук, стабилизатор | D11: 45000
B12: Дорожный день группы | C12: день вылета и день возвращения, доля ставки | D12: 0.5
B13: Суточные на человека в день | C13: за дни съёмок и два дня дороги | D13: 2000
B14: НДС | C14: ставка с 1 января 2026 года | D14: 0.22
B16: жёлтое можно менять | C16: Ставки: оценка Hand Marketing по рынку Москвы на 2026–2027 годы, без НДС.
B18: Hand Marketing · hand-marketing.ru · +7 985 999 87 83 · anarodetsky@hand-marketing.ru

Sheet Съёмки
F3: ВВОДНЫЕ ПО ГОРОДУ · МОЖНО МЕНЯТЬ | K3: РАСЧЁТ · ФОРМУЛЫ
B4: Площадка | C4: Что снимаем | D4: Смен | E4: Выезд | F4: Перелёт на чел., ₽ | G4: Перевес техники, ₽ | H4: Гостиница, ночь, ₽ | I4: Трансфер аэропорт, в одну сторону, ₽ | J4: Трансфер команды и техники, день, ₽ | K4: Группа, ₽ | L4: Техника, ₽ | M4: Дорожные дни, ₽ | N4: Перелёты, ₽ | O4: Гостиница, ₽ | P4: Трансферы команды и техники, ₽ | Q4: Суточные, ₽ | R4: Всего, ₽
B5: Москва, офис | C5: офис, экраны, B2B, руководители и интервью | D5: 1 | E5: 0 | F5: 0 | G5: 0 | H5: 0 | I5: 0 | J5: 12000 | K5: =D5*Ставки!$D$7 | L5: =D5*Ставки!$D$11 | M5: =E5*2*Ставки!$D$7*Ставки!$D$12 | N5: =E5*(F5*Ставки!$D$10+G5) | O5: =E5*(D5+1)*H5*Ставки!$D$10 | P5: =E5*2*I5+D5*J5 | Q5: =E5*(D5+2)*Ставки!$D$13*Ставки!$D$10 | R5: =SUM(K5:Q5)
B6: Валищево | C6: склад днём и ночная смена отдельным выездом | D6: 2 | E6: 0 | F6: 0 | G6: 0 | H6: 0 | I6: 0 | J6: 12000 | K6: =D6*Ставки!$D$7 | L6: =D6*Ставки!$D$11 | M6: =E6*2*Ставки!$D$7*Ставки!$D$12 | N6: =E6*(F6*Ставки!$D$10+G6) | O6: =E6*(D6+1)*H6*Ставки!$D$10 | P6: =E6*2*I6+D6*J6 | Q6: =E6*(D6+2)*Ставки!$D$13*Ставки!$D$10 | R6: =SUM(K6:Q6)
B7: Нижний Новгород | C7: склад и офис, рассвет, сотрудники со стажем, архив | D7: 2 | E7: 1 | F7: 14000 | G7: 12000 | H7: 7500 | I7: 4000 | J7: 14000 | K7: =D7*Ставки!$D$7 | L7: =D7*Ставки!$D$11 | M7: =E7*2*Ставки!$D$7*Ставки!$D$12 | N7: =E7*(F7*Ставки!$D$10+G7) | O7: =E7*(D7+1)*H7*Ставки!$D$10 | P7: =E7*2*I7+D7*J7 | Q7: =E7*(D7+2)*Ставки!$D$13*Ставки!$D$10 | R7: =SUM(K7:Q7)
B8: Санкт-Петербург | C8: офис и склад, город для партнёрской версии | D8: 2 | E8: 1 | F8: 16000 | G8: 12000 | H8: 9500 | I8: 4500 | J8: 16000 | K8: =D8*Ставки!$D$7 | L8: =D8*Ставки!$D$11 | M8: =E8*2*Ставки!$D$7*Ставки!$D$12 | N8: =E8*(F8*Ставки!$D$10+G8) | O8: =E8*(D8+1)*H8*Ставки!$D$10 | P8: =E8*2*I8+D8*J8 | Q8: =E8*(D8+2)*Ставки!$D$13*Ставки!$D$10 | R8: =SUM(K8:Q8)
B9: Минск | C9: вечерняя отгрузка, склад в огнях, офис | D9: 2 | E9: 1 | F9: 24000 | G9: 15000 | H9: 8000 | I9: 4500 | J9: 15000 | K9: =D9*Ставки!$D$7 | L9: =D9*Ставки!$D$11 | M9: =E9*2*Ставки!$D$7*Ставки!$D$12 | N9: =E9*(F9*Ставки!$D$10+G9) | O9: =E9*(D9+1)*H9*Ставки!$D$10 | P9: =E9*2*I9+D9*J9 | Q9: =E9*(D9+2)*Ставки!$D$13*Ставки!$D$10 | R9: =SUM(K9:Q9)
B10: Алматы | C10: первые ворота в темноте, планёрка, рассвет, офис | D10: 2 | E10: 1 | F10: 52000 | G10: 25000 | H10: 11000 | I10: 5000 | J10: 18000 | K10: =D10*Ставки!$D$7 | L10: =D10*Ставки!$D$11 | M10: =E10*2*Ставки!$D$7*Ставки!$D$12 | N10: =E10*(F10*Ставки!$D$10+G10) | O10: =E10*(D10+1)*H10*Ставки!$D$10 | P10: =E10*2*I10+D10*J10 | Q10: =E10*(D10+2)*Ставки!$D$13*Ставки!$D$10 | R10: =SUM(K10:Q10)
B11: Резерв, Москва | C11: погода, доборы переходов, пропущенные кадры | D11: 1 | E11: 0 | F11: 0 | G11: 0 | H11: 0 | I11: 0 | J11: 12000 | K11: =D11*Ставки!$D$7 | L11: =D11*Ставки!$D$11 | M11: =E11*2*Ставки!$D$7*Ставки!$D$12 | N11: =E11*(F11*Ставки!$D$10+G11) | O11: =E11*(D11+1)*H11*Ставки!$D$10 | P11: =E11*2*I11+D11*J11 | Q11: =E11*(D11+2)*Ставки!$D$13*Ставки!$D$10 | R11: =SUM(K11:Q11)
B12: Итого съёмки | D12: =SUM(D5:D11) | K12: =SUM(K5:K11) | L12: =SUM(L5:L11) | M12: =SUM(M5:M11) | N12: =SUM(N5:N11) | O12: =SUM(O5:O11) | P12: =SUM(P5:P11) | Q12: =SUM(Q5:Q11) | R12: =SUM(R5:R11)
B14: О П Ц И Я , В И Т О Г Н Е В Х О Д И Т
B15: Казань (опция) | C15: крупный склад, офис, команда продаж, город | D15: 2 | E15: 1 | F15: 16000 | G15: 12000 | H15: 8000 | I15: 4000 | J15: 14000 | K15: =D15*Ставки!$D$7 | L15: =D15*Ставки!$D$11 | M15: =E15*2*Ставки!$D$7*Ставки!$D$12 | N15: =E15*(F15*Ставки!$D$10+G15) | O15: =E15*(D15+1)*H15*Ставки!$D$10 | P15: =E15*2*I15+D15*J15 | Q15: =E15*(D15+2)*Ставки!$D$13*Ставки!$D$10 | R15: =SUM(K15:Q15)
B17: К А К С Ч И Т А Е М
B18: Группа и техника: смены × ставку. Дорожные дни: два дня × ставку группы × долю со листа «Ставки».
B19: Перелёт: на троих туда и обратно плюс перевес кофров. Гостиница: ночей на одну больше, чем смен, три номера.
B20: Суточные: дни съёмок плюс два дня дороги, на каждого. Цены поездок по тарифам на февраль–май 2027, уточняем при бронировании.
B22: Hand Marketing · hand-marketing.ru · +7 985 999 87 83 · anarodetsky@hand-marketing.ru

Sheet Вопросы
C3: Почему на съёмку едут трое, а не большая группа? | D3: Съёмок 12 смен в шести городах. Большую группу пришлось бы возить или нанимать на месте каждый раз, это дороже и даёт разную картинку. Одни и те же трое знают сценарий, героев и формулы кадров, поэтому снимают быстрее, а все города выглядят как одна компания. Корпоративному фильму без актёров и грима этого состава хватает: так мы снимали руководителей и сотрудников Saint-Gobain из примеров ниже.
C4: Почему на склады по две смены? | D4: Склад живёт по-разному утром, днём и ночью, а в «Сутках без остановки» время в титре всегда настоящее. За одну смену не успеть и склад, и офис, и интервью. В Валищево вторая смена ночная, отдельным выездом.
C5: Где можно сэкономить? | D5: Петербург в одну смену вместо двух: минус 184 500 ₽. Без резервной смены: минус 146 000 ₽, но тогда погода и переносы становятся риском. Меньше стоков: каждый клип 6 000 ₽. Скажите, что важнее, пересчитаем за день.
C6: Изменится ли сумма, если съёмки сдвинутся на весну? | D6: Почти нет: те же смены, люди и поездки. Цены на билеты и гостиницы уточняем при бронировании. Весной светлее и без снега, это меняет картинку и время съёмки, а не смету.
C7: Сколько правок включено? | D7: Три круга правок по каждой из трёх версий, как в ТЗ. Правки сценария до съёмок тоже входят.
C8: Что если понадобится английская или казахская версия? | D8: Посчитаем отдельно, когда понадобится: перевод, диктор, субтитры и графика на другом языке. Съёмки при этом не меняются.
B10: Hand Marketing · hand-marketing.ru · +7 985 999 87 83 · anarodetsky@hand-marketing.ru
