Workbook

Sheet Сводка
A1: ООО «Хэнд-маркетинг» · предложение для вендор-листа ГК «Киевская площадь»
A2: Заказчик: ООО «Центральная Площадь», ИНН 7730338370. Срок подачи: 23.10.2026.
A4: Общие условия
A5: Оказываем направлений | B5: =COUNTIF(C18:C48,"Оказываем")&" из 31"
A6: Стоимость работ | B6: По каждой позиции на листе «КП», ставки на листе «Прайс»
A7: НДС | B7: ="Цены без НДС. НДС "&TEXT(Прайс!$B$5,"0%")&" начисляется сверху"
A8: Скидка | B8: ="Скидка участника вендор-листа "&TEXT(Прайс!$B$6,"0%")&" на работу агентства уже в КП: креатив, дизайн, тексты, CGI, фото- и видеосъемка, продюсирование, концепции, эскизы, агентская комиссия. На производство, тиражи и закупки скидку даем от объема конкретного заказа."
A9: Условия оплаты: услуги | B9: ="100% по факту, оплата в течение "&Прайс!$B$8&" р.д. после акта, без аванса"
A10: Условия оплаты: услуги с расходами на подрядчиков | B10: ="Аванс "&TEXT(Прайс!$B$11,"0%")&" на расходы подрядчиков, остаток в течение "&Прайс!$B$8&" р.д. после акта"
A11: Условия оплаты: производство, закупки, мероприятия | B11: ="Аванс "&TEXT(Прайс!$B$7,"0%")&", остаток "&TEXT(1-Прайс!$B$7,"0%")&" после акта"
A12: Фиксация цен | B12: ="Работа агентства: "&Прайс!$B$9&" мес. с даты КП. Производство и закупки: "&Прайс!$B$10&" мес. с даты КП, дальше пересчет по ценам поставщиков"
A13: Юрлица холдинга | B13: Один закрепленный менеджер и одинаковые условия для всех 7 юрлиц из письма № 38/2026
A14: Менеджер | B14: Народецкий Александр, Client Service Director, +7 985 999 87 83, anarodetsky@hand-marketing.ru
A16: Направления
A17: № | B17: Направление | C17: Участие | D17: Итог расчета по запросу ТЗ со скидкой, руб. без НДС | E17: Условия оплаты | F17: Фиксация
A18: 1 | B18: Рекламно-производственное агентство | C18: Оказываем | D18: Часть расчетов по запросу, см. лист «КП» | E18: ="Аванс "&TEXT(Прайс!$B$7,"0%")&", остаток "&TEXT(1-Прайс!$B$7,"0%")&" после акта" | F18: =Прайс!$B$10&" мес."
A19: 2 | B19: Наружная реклама | C19: Не оказываем
A20: 3 | B20: Монтажные и демонтажные работы | C20: Оказываем | D20: =КП!J21 | E20: ="100% по факту, оплата в течение "&Прайс!$B$8&" р.д. после акта, без аванса" | F20: =Прайс!$B$9&" мес."
A21: 4 | B21: Альпинисты, высотные работы | C21: Не оказываем
A22: 5 | B22: Пластиковые карты | C22: Оказываем | D22: Несколько расчетов, см. лист «КП» | E22: ="Аванс "&TEXT(Прайс!$B$7,"0%")&", остаток "&TEXT(1-Прайс!$B$7,"0%")&" после акта" | F22: =Прайс!$B$10&" мес."
A23: 6 | B23: Брендированные вешалки | C23: Оказываем | D23: Несколько расчетов, см. лист «КП» | E23: ="Аванс "&TEXT(Прайс!$B$7,"0%")&", остаток "&TEXT(1-Прайс!$B$7,"0%")&" после акта" | F23: =Прайс!$B$10&" мес."
A24: 7 | B24: Брендированные тишью | C24: Оказываем | D24: Несколько расчетов, см. лист «КП» | E24: ="Аванс "&TEXT(Прайс!$B$7,"0%")&", остаток "&TEXT(1-Прайс!$B$7,"0%")&" после акта" | F24: =Прайс!$B$10&" мес."
A25: 8 | B25: Брендированные кофры | C25: Оказываем | D25: Несколько расчетов, см. лист «КП» | E25: ="Аванс "&TEXT(Прайс!$B$7,"0%")&", остаток "&TEXT(1-Прайс!$B$7,"0%")&" после акта" | F25: =Прайс!$B$10&" мес."
A26: 9 | B26: CGI & AI-студия, CGI-ролики | C26: Оказываем | D26: =КП!J69 | E26: ="100% по факту, оплата в течение "&Прайс!$B$8&" р.д. после акта, без аванса" | F26: =Прайс!$B$9&" мес."
A27: 10 | B27: Брендинг | C27: Оказываем | D27: =КП!J77 | E27: ="100% по факту, оплата в течение "&Прайс!$B$8&" р.д. после акта, без аванса" | F27: =Прайс!$B$9&" мес."
A28: 11 | B28: Дизайн макетов | C28: Оказываем | D28: Несколько расчетов, см. лист «КП» | E28: ="100% по факту, оплата в течение "&Прайс!$B$8&" р.д. после акта, без аванса" | F28: =Прайс!$B$9&" мес."
A29: 12 | B29: Написание текстов | C29: Оказываем | D29: Несколько расчетов, см. лист «КП» | E29: ="100% по факту, оплата в течение "&Прайс!$B$8&" р.д. после акта, без аванса" | F29: =Прайс!$B$9&" мес."
A30: 13 | B30: Продюсер съемок | C30: Оказываем | D30: =КП!J95 | E30: ="Аванс "&TEXT(Прайс!$B$11,"0%")&" на расходы подрядчиков, остаток в течение "&Прайс!$B$8&" р.д. после акта" | F30: =Прайс!$B$9&" мес."
A31: 14 | B31: Фотограф | C31: Оказываем | D31: Несколько расчетов, см. лист «КП» | E31: ="100% по факту, оплата в течение "&Прайс!$B$8&" р.д. после акта, без аванса" | F31: =Прайс!$B$9&" мес."
A32: 15 | B32: Видеограф | C32: Оказываем | D32: Несколько расчетов, см. лист «КП» | E32: ="100% по факту, оплата в течение "&Прайс!$B$8&" р.д. после акта, без аванса" | F32: =Прайс!$B$9&" мес."
A33: 16 | B33: Мерч, корпоративные подарки | C33: Оказываем | D33: Часть расчетов по запросу, см. лист «КП» | E33: ="Аванс "&TEXT(Прайс!$B$7,"0%")&", остаток "&TEXT(1-Прайс!$B$7,"0%")&" после акта" | F33: =Прайс!$B$10&" мес."
A34: 17 | B34: Сувенирная продукция, PR-боксы | C34: Оказываем | D34: Часть расчетов по запросу, см. лист «КП» | E34: ="Аванс "&TEXT(Прайс!$B$7,"0%")&", остаток "&TEXT(1-Прайс!$B$7,"0%")&" после акта" | F34: =Прайс!$B$10&" мес."
A35: 18 | B35: Брендированная вода | C35: Оказываем | D35: Несколько расчетов, см. лист «КП» | E35: ="Аванс "&TEXT(Прайс!$B$7,"0%")&", остаток "&TEXT(1-Прайс!$B$7,"0%")&" после акта" | F35: =Прайс!$B$10&" мес."
A36: 19 | B36: Свечи и диффузоры | C36: Оказываем | D36: Несколько расчетов, см. лист «КП» | E36: ="Аванс "&TEXT(Прайс!$B$7,"0%")&", остаток "&TEXT(1-Прайс!$B$7,"0%")&" после акта" | F36: =Прайс!$B$10&" мес."
A37: 20 | B37: Шоколад | C37: Оказываем | D37: =КП!J174 | E37: ="Аванс "&TEXT(Прайс!$B$7,"0%")&", остаток "&TEXT(1-Прайс!$B$7,"0%")&" после акта" | F37: =Прайс!$B$10&" мес."
A38: 21 | B38: Форма для сотрудников | C38: Оказываем | D38: Несколько расчетов, см. лист «КП» | E38: ="Аванс "&TEXT(Прайс!$B$7,"0%")&", остаток "&TEXT(1-Прайс!$B$7,"0%")&" после акта" | F38: =Прайс!$B$10&" мес."
A39: 22 | B39: Агентство по организации мероприятий | C39: Оказываем | D39: =КП!J184 | E39: ="Аванс "&TEXT(Прайс!$B$7,"0%")&", остаток "&TEXT(1-Прайс!$B$7,"0%")&" после акта" | F39: =Прайс!$B$10&" мес."
A40: 23 | B40: Декорирование, флористика | C40: Оказываем | D40: Часть расчетов по запросу, см. лист «КП» | E40: ="Аванс "&TEXT(Прайс!$B$7,"0%")&", остаток "&TEXT(1-Прайс!$B$7,"0%")&" после акта" | F40: =Прайс!$B$10&" мес."
A41: 24 | B41: Кейтеринг | C41: Оказываем | D41: Несколько расчетов, см. лист «КП» | E41: ="Аванс "&TEXT(Прайс!$B$7,"0%")&", остаток "&TEXT(1-Прайс!$B$7,"0%")&" после акта" | F41: =Прайс!$B$10&" мес."
A42: 25 | B42: Звук и свет | C42: Оказываем | D42: =КП!J213 | E42: ="Аванс "&TEXT(Прайс!$B$11,"0%")&" на расходы подрядчиков, остаток в течение "&Прайс!$B$8&" р.д. после акта" | F42: =Прайс!$B$9&" мес."
...

Sheet КП
A1: Коммерческое предложение ООО «Хэнд-маркетинг» · вендор-лист маркетинговых подрядчиков ГК «Киевская площадь»
A2: Объекты: ТРЦ «Ривьера», Центральный рынок, МФК «Венеция», ТЦ «Времена года», ТЦ «ЦДМ на Лубянке». Расчеты по запросам ТЗ. Цены в рублях без НДС, НДС 22% начисляется сверху. Доставка в расчетах по адресу: Москва, ул. Автозаводская, д. 18.
A4: № | B4: Направление | C4: Объекты | D4: Расчет по запросу ТЗ | E4: Ед. изм. | F4: Объем | G4: Цена за ед. по прайсу, руб. без НДС | H4: Стоимость по прайсу, руб. без НДС | I4: Скидка | J4: Стоимость со скидкой, руб. без НДС | K4: НДС 22%, руб. | L4: Итого с НДС, руб. | M4: Срок выполнения | N4: Условия оплаты | O4: Фиксация цены | P4: Примечание
A5: 1 | B5: Рекламно-производственное агентство | C5: Венеция, Ривьера | D5: Позиция ТЗ | N5: ="Аванс "&TEXT(Прайс!$B$7,"0%")&", остаток "&TEXT(1-Прайс!$B$7,"0%")&" после акта" | O5: =Прайс!$B$10&" мес." | P5: Объемные буквы считаем по макету: цену задают шрифт, борт и тип подсветки. Гарантия 12 мес. на конструкции, 12 мес. на электрику и подсветку. Ночной монтаж 23:00-07:00: плюс 30% к стоимости монтажа, в расчете лайтбокса уже учтен. Доставка до объекта в расчетах отдельной строкой. Замер бесплатно, выезд в течение 1 р.д.
D6: (1) Лайтбокс 1,2 × 1,8 м с монтажом на стену | E6: итого | H6: =SUM(H7:H10) | J6: =SUM(J7:J10) | K6: =SUM(K7:K10) | L6: =SUM(L7:L10) | M6: 7 р.д. производство, монтаж 1 ночь
D7: Лайтбокс односторонний 1,2 × 1,8 м, LED-подсветка, изготовление | E7: шт. | F7: 1 | G7: =Прайс!E17 | H7: =ROUND(F7*G7,0) | I7: 0 | J7: =ROUND(H7*(1-I7),0) | K7: =ROUND(J7*Прайс!$B$5,0) | L7: =J7+K7
D8: Монтаж лайтбокса на стену, подключение | E8: шт. | F8: 1 | G8: =Прайс!E18 | H8: =ROUND(F8*G8,0) | I8: 0 | J8: =ROUND(H8*(1-I8),0) | K8: =ROUND(J8*Прайс!$B$5,0) | L8: =J8+K8
D9: Доплата за ночной монтаж 23:00-07:00, 30% к монтажу | E9: компл. | F9: 1 | G9: =Прайс!E19 | H9: =ROUND(F9*G9,0) | I9: 0 | J9: =ROUND(H9*(1-I9),0) | K9: =ROUND(J9*Прайс!$B$5,0) | L9: =J9+K9 | P9: монтаж ночью
D10: Доставка конструкций на объект по Москве | E10: рейс | F10: 1 | G10: =Прайс!E20 | H10: =ROUND(F10*G10,0) | I10: 0 | J10: =ROUND(H10*(1-I10),0) | K10: =ROUND(J10*Прайс!$B$5,0) | L10: =J10+K10 | P10: до Автозаводской, 18
D11: (2) Объемные буквы 40 см, 10 знаков, монтаж на высоте 4 м | M11: Расчет за 2 р.д. после макета и замера
D12: Объемная буква с внутренней подсветкой, высота 40 см | E12: знак | F12: 10 | G12: По запросу | J12: По запросу | L12: По запросу
D13: Блок питания, коммутация, подложка вывески | E13: компл. | F13: 1 | G13: По запросу | J13: По запросу | L13: По запросу
D14: Монтаж вывески на высоте до 4 м, с вышкой | E14: компл. | F14: 1 | G14: По запросу | J14: По запросу | L14: По запросу
D15: (3) Витрина 3 × 2,5 м: пленка + 2 фигуры ПВХ | E15: итого | H15: =SUM(H16:H18) | J15: =SUM(J16:J18) | K15: =SUM(K16:K18) | L15: =SUM(L16:L18) | M15: 5 р.д. с монтажом
D16: Пленка с полноцветной печатью и ламинацией, оклейка витрины | E16: м² | F16: 7.5 | G16: =Прайс!E24 | H16: =ROUND(F16*G16,0) | I16: 0 | J16: =ROUND(H16*(1-I16),0) | K16: =ROUND(J16*Прайс!$B$5,0) | L16: =J16+K16 | P16: 3 × 2,5 м = 7,5 м², с оклейкой
D17: Напольная фигура ПВХ 5 мм до 1,8 м, полноцветная печать, опора | E17: шт. | F17: 2 | G17: =Прайс!E25 | H17: =ROUND(F17*G17,0) | I17: 0 | J17: =ROUND(H17*(1-I17),0) | K17: =ROUND(J17*Прайс!$B$5,0) | L17: =J17+K17
D18: Доставка конструкций на объект по Москве | E18: рейс | F18: 1 | G18: =Прайс!E20 | H18: =ROUND(F18*G18,0) | I18: 0 | J18: =ROUND(H18*(1-I18),0) | K18: =ROUND(J18*Прайс!$B$5,0) | L18: =J18+K18 | P18: фигуры, до Автозаводской, 18
A19: 2 | B19: Наружная реклама | C19: Времена Года, Венеция | D19: Не оказываем | P19: Направление не входит в наш профиль. Расчет не предоставляем.
A20: 3 | B20: Монтажные и демонтажные работы | C20: ЦДМ, Ривьера | D20: Позиция ТЗ | N20: ="100% по факту, оплата в течение "&Прайс!$B$8&" р.д. после акта, без аванса" | O20: =Прайс!$B$9&" мес." | P20: Ставка ночной смены уже ночная, доплата 30% к ней не применяется. Срочный выезд в течение 24 ч: плюс 25% к стоимости смен. Ручной инструмент входит в ставку, вышки по прайсу. Работаем по регламенту ТЦ: пропуска, ночной режим, вывоз мусора.
D21: Новогодний декор в атриуме: 4 монтажника, 2 ночные смены монтажа + 1 ночная смена демонтажа | E21: итого | H21: =SUM(H22:H25) | J21: =SUM(J22:J25) | K21: =SUM(K22:K25) | L21: =SUM(L22:L25) | M21: Выход по графику ТЦ, бригада до 12 человек на смену
D22: Монтажник, смена 8 ч, ночная | E22: чел.-смена | F22: 12 | G22: =Прайс!E28 | H22: =ROUND(F22*G22,0) | I22: 0 | J22: =ROUND(H22*(1-I22),0) | K22: =ROUND(J22*Прайс!$B$5,0) | L22: =J22+K22 | P22: 4 чел. × 3 смены
D23: Грузовой автомобиль до 3 т, рейс по Москве | E23: рейс | F23: 2 | G23: =Прайс!E29 | H23: =ROUND(F23*G23,0) | I23: 0 | J23: =ROUND(H23*(1-I23),0) | K23: =ROUND(J23*Прайс!$B$5,0) | L23: =J23+K23 | P23: завоз и вывоз
D24: Вывоз упаковки и мусора | E24: рейс | F24: 1 | G24: =Прайс!E30 | H24: =ROUND(F24*G24,0) | I24: 0 | J24: =ROUND(H24*(1-I24),0) | K24: =ROUND(J24*Прайс!$B$5,0) | L24: =J24+K24
D25: Аренда вышки-туры до 6 м с доставкой | E25: сутки | F25: 3 | G25: =Прайс!E31 | H25: =ROUND(F25*G25,0) | I25: 0 | J25: =ROUND(H25*(1-I25),0) | K25: =ROUND(J25*Прайс!$B$5,0) | L25: =J25+K25 | P25: на каждую ночь
A26: 4 | B26: Альпинисты, высотные работы | C26: Времена Года, ЦДМ | D26: Не оказываем | P26: Направление не входит в наш профиль. Расчет не предоставляем.
A27: 5 | B27: Пластиковые карты | C27: Венеция | D27: Позиция ТЗ | N27: ="Аванс "&TEXT(Прайс!$B$7,"0%")&", остаток "&TEXT(1-Прайс!$B$7,"0%")&" после акта" | O27: =Прайс!$B$10&" мес." | P27: Минимальный тираж 500 шт. Нумерация и кодировка полосы по вашему списку, проверяем на вашем считывателе до тиража. Дозаказ на тех же условиях, клише храним 12 месяцев.
D28: Подарочные карты, тираж 1 000 шт. | E28: итого | H28: =SUM(H29:H31) | J28: =SUM(J29:J31) | K28: =SUM(K29:K31) | L28: =SUM(L29:L31) | M28: 10 р.д. после утверждения образца, образец 5 р.д.
D29: Карта ПВХ 0,76 мм CR80, печать 4+4, матовая ламинация, фольга, HiCo, лазерная нумерация | E29: шт. | F29: 1000 | G29: =Прайс!E32 | H29: =ROUND(F29*G29,0) | I29: 0 | J29: =ROUND(H29*(1-I29),0) | K29: =ROUND(J29*Прайс!$B$5,0) | L29: =J29+K29
D30: Клише для тиснения фольгой, подготовка к печати | E30: компл. | F30: 1 | G30: =Прайс!E33 | H30: =ROUND(F30*G30,0) | I30: 0 | J30: =ROUND(H30*(1-I30),0) | K30: =ROUND(J30*Прайс!$B$5,0) | L30: =J30+K30
D31: Доставка тиража по Москве | E31: рейс | F31: 1 | G31: =Прайс!E35 | H31: =ROUND(F31*G31,0) | I31: 0 | J31: =ROUND(H31*(1-I31),0) | K31: =ROUND(J31*Прайс!$B$5,0) | L31: =J31+K31 | P31: до Автозаводской, 18
D32: Пробный образец | E32: компл. | F32: 1 | G32: =Прайс!E34 | H32: =ROUND(F32*G32,0) | I32: 0 | J32: =ROUND(H32*(1-I32),0) | K32: =ROUND(J32*Прайс!$B$5,0) | L32: =J32+K32 | M32: 5 р.д.
A33: 6 | B33: Брендированные вешалки | C33: Венеция | D33: Позиция ТЗ | N33: ="Аванс "&TEXT(Прайс!$B$7,"0%")&", остаток "&TEXT(1-Прайс!$B$7,"0%")&" после акта" | O33: =Прайс!$B$10&" мес." | P33: Тиражи 200 и 500: флок ближайшего цвета из наличия. Тираж 1 000: флок по Pantone брендбука. Логотип на гладкой вставке или тиснением по рекомендации производителя, проверяем на образце. Групповая упаковка с защитой крючков. Брак меняем за свой счет.
D34: Тираж 200 шт. | E34: итого | H34: =SUM(H35:H36) | J34: =SUM(J35:J36) | K34: =SUM(K35:K36) | L34: =SUM(L35:L36) | M34: 15 р.д. после утверждения образца
D35: Вешалка флокированная с перекладиной, поворотный крючок, логотип 1 цвет, тираж 200 | E35: шт. | F35: 200 | G35: =Прайс!E36 | H35: =ROUND(F35*G35,0) | I35: 0 | J35: =ROUND(H35*(1-I35),0) | K35: =ROUND(J35*Прайс!$B$5,0) | L35: =J35+K35
D36: Доставка тиража по Москве | E36: рейс | F36: 1 | G36: =Прайс!E40 | H36: =ROUND(F36*G36,0) | I36: 0 | J36: =ROUND(H36*(1-I36),0) | K36: =ROUND(J36*Прайс!$B$5,0) | L36: =J36+K36 | P36: до Автозаводской, 18
D37: Тираж 500 шт. | E37: итого | H37: =SUM(H38:H39) | J37: =SUM(J38:J39) | K37: =SUM(K38:K39) | L37: =SUM(L38:L39) | M37: 15 р.д. после утверждения образца
D38: Вешалка флокированная с перекладиной, поворотный крючок, логотип 1 цвет, тираж 500 | E38: шт. | F38: 500 | G38: =Прайс!E37 | H38: =ROUND(F38*G38,0) | I38: 0 | J38: =ROUND(H38*(1-I38),0) | K38: =ROUND(J38*Прайс!$B$5,0) | L38: =J38+K38
D39: Доставка тиража по Москве | E39: рейс | F39: 1 | G39: =Прайс!E40 | H39: =ROUND(F39*G39,0) | I39: 0 | J39: =ROUND(H39*(1-I39),0) | K39: =ROUND(J39*Прайс!$B$5,0) | L39: =J39+K39 | P39: до Автозаводской, 18
D40: Тираж 1 000 шт. | E40: итого | H40: =SUM(H41:H42) | J40: =SUM(J41:J42) | K40: =SUM(K41:K42) | L40: =SUM(L41:L42) | M40: 30-40 р.д. после утверждения образца
D41: Вешалка флокированная с перекладиной, поворотный крючок, логотип 1 цвет, тираж 1000 | E41: шт. | F41: 1000 | G41: =Прайс!E38 | H41: =ROUND(F41*G41,0) | I41: 0 | J41: =ROUND(H41*(1-I41),0) | K41: =ROUND(J41*Прайс!$B$5,0) | L41: =J41+K41
...

Sheet Прайс
A1: Прайс ООО «Хэнд-маркетинг» для вендор-листа ГК «Киевская площадь»
A2: Цены в рублях без НДС, НДС 22% начисляется сверху. Желтые ячейки: параметры условий, от них считаются КП и сводка.
A4: Параметр | B4: Значение | C4: Комментарий
A5: Ставка НДС, начисляется сверху | B5: 0.22 | C5: ООО «Хэнд-маркетинг» на ОСНО
A6: Скидка участника вендор-листа на работу агентства | B6: 0.1 | C6: Креатив, дизайн, тексты, CGI, съемка, концепции, эскизы, агентская комиссия. Подрядчики, аренда, персонал, производство: скидка от объема
A7: Аванс по производству и закупкам | B7: 0.7 | C7: Остаток после подписания акта
A8: Срок оплаты услуг после акта, рабочих дней | B8: 10 | C8: Услуги без аванса
A9: Фиксация цен на работу агентства, месяцев | B9: 6 | C9: С даты КП
A10: Срок действия цен производства и закупок, месяцев | B10: 3 | C10: С даты КП, дальше пересчет по ценам поставщиков
A11: Аванс по услугам с расходами на подрядчиков | B11: 0.5 | C11: Съемка с моделями, звук и свет, диджей, звукорежиссер, персонал
A12: Доплата за ночной монтаж 23:00-07:00 к стоимости монтажа | B12: 0.3 | C12: Для позиций 1, 23, 31
A13: Доплата за срочный выезд в течение 24 ч к стоимости смен | B13: 0.25 | C13: Для позиции 3
A14: Агентская комиссия на мероприятия | B14: 0.12 | C14: От суммы сметы мероприятия
A16: Поз. ТЗ | B16: Направление | C16: Услуга или изделие | D16: Ед. изм. | E16: Цена по прайсу, руб. без НДС | F16: Цена для вендор-листа, руб. без НДС | G16: Примечание
A17: 1 | B17: Рекламно-производственное агентство | C17: Лайтбокс односторонний 1,2 × 1,8 м, LED-подсветка, изготовление | D17: шт. | E17: 44000 | F17: =E17 | G17: Профиль алюминиевый, лицевая панель акрил, LED-модули
A18: 1 | B18: Рекламно-производственное агентство | C18: Монтаж лайтбокса на стену, подключение | D18: шт. | E18: 9000 | F18: =E18
A19: 1 | B19: Рекламно-производственное агентство | C19: Доплата за ночной монтаж 23:00-07:00, 30% к монтажу | D19: компл. | E19: 2700 | F19: =E19 | G19: Только если монтаж ночью
A20: 1 | B20: Рекламно-производственное агентство | C20: Доставка конструкций на объект по Москве | D20: рейс | E20: 6500 | F20: =E20
A21: 1 | B21: Рекламно-производственное агентство | C21: Объемная буква с внутренней подсветкой, высота 40 см | D21: знак | E21: По запросу | F21: По запросу | G21: Борт ПВХ или алюминий, лицо акрил, LED
A22: 1 | B22: Рекламно-производственное агентство | C22: Блок питания, коммутация, подложка вывески | D22: компл. | E22: По запросу | F22: По запросу
A23: 1 | B23: Рекламно-производственное агентство | C23: Монтаж вывески на высоте до 4 м, с вышкой | D23: компл. | E23: По запросу | F23: По запросу
A24: 1 | B24: Рекламно-производственное агентство | C24: Пленка с полноцветной печатью и ламинацией, оклейка витрины | D24: м² | E24: 2200 | F24: =E24 | G24: Печать 1440 dpi, ламинация матовая или глянцевая
A25: 1 | B25: Рекламно-производственное агентство | C25: Напольная фигура ПВХ 5 мм до 1,8 м, полноцветная печать, опора | D25: шт. | E25: 8500 | F25: =E25
A26: 1 | B26: Рекламно-производственное агентство | C26: Выезд на замер по Москве | D26: выезд | E26: Бесплатно | F26: Бесплатно | G26: Бесплатно. Выезд в течение 1 рабочего дня
A27: 3 | B27: Монтажные и демонтажные работы | C27: Монтажник, смена 8 ч, дневная | D27: чел.-смена | E27: 6800 | F27: =E27
A28: 3 | B28: Монтажные и демонтажные работы | C28: Монтажник, смена 8 ч, ночная | D28: чел.-смена | E28: 8800 | F28: =E28
A29: 3 | B29: Монтажные и демонтажные работы | C29: Грузовой автомобиль до 3 т, рейс по Москве | D29: рейс | E29: 8500 | F29: =E29
A30: 3 | B30: Монтажные и демонтажные работы | C30: Вывоз упаковки и мусора | D30: рейс | E30: 6500 | F30: =E30
A31: 3 | B31: Монтажные и демонтажные работы | C31: Аренда вышки-туры до 6 м с доставкой | D31: сутки | E31: 4800 | F31: =E31 | G31: Ручной инструмент входит в ставку смены
A32: 5 | B32: Пластиковые карты | C32: Карта ПВХ 0,76 мм CR80, печать 4+4, матовая ламинация, фольга, HiCo, лазерная нумерация | D32: шт. | E32: 38 | F32: =E32
A33: 5 | B33: Пластиковые карты | C33: Клише для тиснения фольгой, подготовка к печати | D33: компл. | E33: 6000 | F33: =E33 | G33: Один раз на макет
A34: 5 | B34: Пластиковые карты | C34: Пробный образец карты с отделкой и персонализацией | D34: компл. | E34: 9500 | F34: =E34 | G34: Засчитывается в тираж
A35: 5 | B35: Пластиковые карты | C35: Доставка тиража по Москве | D35: рейс | E35: 2500 | F35: =E35
A36: 6 | B36: Брендированные вешалки | C36: Вешалка флокированная с перекладиной, поворотный крючок, логотип 1 цвет, тираж 200 | D36: шт. | E36: 290 | F36: =E36 | G36: Цвет флока: ближайший из наличия
A37: 6 | B37: Брендированные вешалки | C37: Вешалка флокированная с перекладиной, поворотный крючок, логотип 1 цвет, тираж 500 | D37: шт. | E37: 240 | F37: =E37 | G37: Цвет флока: ближайший из наличия
A38: 6 | B38: Брендированные вешалки | C38: Вешалка флокированная с перекладиной, поворотный крючок, логотип 1 цвет, тираж 1000 | D38: шт. | E38: 210 | F38: =E38 | G38: Цвет флока по Pantone брендбука
A39: 6 | B39: Брендированные вешалки | C39: Образец вешалки с логотипом | D39: шт. | E39: 3500 | F39: =E39
A40: 6 | B40: Брендированные вешалки | C40: Доставка тиража по Москве | D40: рейс | E40: 6500 | F40: =E40
A41: 7 | B41: Брендированные тишью | C41: Тишью 28 г/м² в цвет брендбука, 50 × 70 см, флексопечать паттерна 1 цвет Pantone | D41: лист | E41: 32 | F41: =E41
A42: 7 | B42: Брендированные тишью | C42: Тишью 28 г/м² в цвет брендбука, 70 × 100 см, флексопечать паттерна 1 цвет Pantone | D42: лист | E42: 54 | F42: =E42
...
